<?xml version='1.0'?>
<sdf version='1.6'>

  <model name='vsssoccer_robot'>

    <link name='base'>
      <inertial>
        <pose frame=''>0.001453 -0.000453 0.029787 0 0 0</pose> <!-- m m m rad rad rad -->
        <inertia>
          <!-- kg.m² -->
          <!-- <ixx>0.00034252</ixx> -->
          <!-- <ixx>0.0035586</ixx> -->
          <!-- <ixx>1</ixx> -->
          <ixx>0.0004219</ixx>
          <!-- <ixx>0.5</ixx> -->
          <!-- com ixx=0.5 robo escorragava em momentos aleatórios e gazebo quebrou apos alguns segundos -->
          <ixy>0</ixy>
          <ixz>0</ixz>
          <!-- <iyy>0.00034252</iyy> -->
          <!-- <iyy>0.009558</iyy> -->
          <!-- <iyy>1</iyy> -->
          <iyy>0.0004219</iyy>
          <!-- <iyy>0.055</iyy> -->
          <iyz>0</iyz>
          <!-- <izz>0.00034252</izz> -->
          <!-- <izz>0.009558</izz> -->
          <!-- <izz>1</izz> -->
          <izz>0.0004219</izz>
          <!-- <izz>0.000004219</izz> -->
          <!-- com izz=0.000004219 robo escapava mais vezes da trajetoria da circunferencia, mas ela continou com o mesmo diametrp -->
          <!-- <izz>0.055</izz> -->
          <!-- com izz=0.055 robo não conseguia virar e ia reto, ou seja, não fazia a circunferencia -->
        </inertia>
        <mass>0.45</mass> <!-- kg -->
        <!-- <mass>2.28349</mass> -->
      </inertial>
      <pose frame=''>0 0 0 0 0 0</pose>
      <kinematic>0</kinematic>
      <gravity>1</gravity>

      <visual name='base_visual'>
        <pose frame=''>0 0 0.04 0 0 0</pose>
        <geometry>
          <box>
            <size>0.075 0.075 0.075</size>
          </box>
        </geometry>
        <material>
          <script>
            <uri>file://media/materials/scripts/gazebo.material</uri>
            <name>Gazebo/White</name>
          </script>
        </material>
      </visual>
      <collision name='base_collision'>
        <pose frame=''>0 0 0.04 0 0 0</pose>
        <geometry>
          <box>
            <size>0.075 0.075 0.075</size>
          </box>
        </geometry>
        <surface>
          <friction>
            <ode>
              <mu>1</mu>
              <mu2>1</mu2>
              <!-- 1 ou 0.8 fizeram a mesma circuferencia para vel 4 e 2  -->
              <!-- <mu>0.8</mu>
              <mu2>0.8</mu2> -->
              <!-- <mu>0</mu>
              <mu2>0</mu2> -->
            </ode>
          </friction>
          <contact>
            <ode>
              <kp>1e+13</kp>
              <kd>1</kd>
            </ode>
            <bullet>
              <kp>1e+13</kp>
              <kd>1</kd>
            </bullet>
          </contact>
        </surface>
      </collision>
  
      <visual name='rear_wheel_visual'>
        <!-- <pose frame=''>-0.03 0 0.004 0 1.5707 1.5707</pose> -->
        <pose frame=''>-0.0325 0 0.004 0 0 0</pose>
        <geometry>
          <sphere>
            <radius>0.005</radius>
          </sphere>
        </geometry>
        <material>
          <script>
            <uri>file://media/materials/scripts/gazebo.material</uri>
            <name>Gazebo/Black</name>
          </script>
        </material>
      </visual>
      <collision name='rear_wheel_collision'>
        <!-- <pose frame=''>-0.03 0 0.004 0 1.5707 1.5707</pose> -->
        <pose frame=''>-0.0325 0 0.004 0 0 0</pose>
        <geometry>
          <sphere>
            <radius>0.005</radius>
          </sphere>
        </geometry>
        <surface>
          <friction>
            <ode>
              <!-- <mu>0.3</mu>
              <mu2>0.3</mu2> -->
              <mu>0.1</mu>
              <mu2>0.1</mu2>
              <!-- A circuferencia foi igual com 0.3 e 0 para velocidades 4 e 2 -->
              <!-- A inercia do robo parado alterou. Para mu=0 robo deslizava. Para mu=0.3 robo desliza pouquissimo -->
              <!-- <mu>0</mu>
              <mu2>0</mu2> -->
            </ode>
          </friction>
          <contact>
            <ode>
              <kp>1e+13</kp>
              <kd>1</kd>
            </ode>
            <bullet>
              <kp>1e+13</kp>
              <kd>1</kd>
            </bullet>
          </contact>
        </surface>
      </collision>

      <visual name='front_wheel_visual'>
        <!-- <pose frame=''>0.03 0 0.004 0 1.5707 1.5707</pose> -->
        <pose frame=''>0.0325 0 0.004 0 0 0</pose>
        <geometry>
          <sphere>
            <radius>0.005</radius>
          </sphere>
        </geometry>
        <material>
          <script>
            <uri>file://media/materials/scripts/gazebo.material</uri>
            <name>Gazebo/Black</name>
          </script>
        </material>
      </visual>
      <collision name='front_wheel_collision'>
        <!-- <pose frame=''>0.03 0 0.004 0 1.5707 1.5707</pose> -->
        <pose frame=''>0.0325 0 0.004 0 0 0</pose>
        <geometry>
          <sphere>
            <radius>0.005</radius>
          </sphere>
        </geometry>
        <surface>
          <friction>
            <ode>
              <!-- <mu>0.3</mu>
              <mu2>0.3</mu2> -->
              <mu>0.1</mu>
              <mu2>0.1</mu2>
              <!-- A circuferencia foi igual com 0.3 e 0 para velocidades 4 e 2 -->
              <!-- A inercia do robo parado alterou. Para mu=0 robo deslizava. Para mu=0.3 robo desliza pouquissimo -->
              <!-- <mu>0</mu>
              <mu2>0</mu2> -->
            </ode>
          </friction>
          <contact>
            <ode>
              <kp>1e+13</kp>
              <kd>1</kd>
            </ode>
            <bullet>
              <kp>1e+13</kp>
              <kd>1</kd>
            </bullet>
          </contact>
        </surface>
      </collision>
    </link>
 
    <link name='left_wheel'>
      <!-- <pose frame=''>0 0.035 0.018 0 0 0</pose> -->
      <!-- <pose frame=''>0 0.0345 0.019 0 0 0</pose> -->
      <!-- <pose frame=''>0 0.0345 0.0158 0 0 0</pose> -->
      <!-- <pose frame=''>0 0.0345 0.0155 0 0 0</pose> -->
      <pose frame=''>0 0.0345 0.014 0 0 0</pose>
      <inertial>
        <inertia>
        <!-- corrigir inercia paralela -->
          <!-- <ixx>0.001</ixx> -->
          <!-- <ixx>7.3e-7</ixx> -->
          <ixx>0.000000365</ixx>
          <!-- <ixx>3.65e-7</ixx> -->
          <!-- <ixx>0.000001445</ixx> -->
          <ixy>0</ixy>
          <ixz>0</ixz>
          <!-- <iyy>0.001</iyy> -->
          <!-- <iyy>0.000001445</iyy> -->
          <!-- <iyy>7.225e-7</iyy> -->
          <iyy>0.000000723</iyy>
          <iyz>0</iyz>
          <!-- <izz>0.001</izz> -->
          <!-- <izz>7.3e-7</izz> -->
          <!-- <izz>3.65e-7</izz> -->
          <!-- <izz>0.000000723</izz> -->
          <!-- <izz>0.000001445</izz> -->
          <izz>0.000000365</izz>
        </inertia>
        <!-- 5 gramas -->
        <mass>0.005</mass>
        <pose frame=''>0 0 0 0 0 0</pose>
      </inertial>
      <kinematic>0</kinematic>
      <gravity>1</gravity>
      <visual name='visual'>
        <pose frame=''>0 0 0 0 1.5707 1.5707</pose>
        <geometry>
          <cylinder>
            <radius>0.017</radius>
            <length>0.003</length>
          </cylinder>
        </geometry>
        <material>
          <script>
            <uri>file://media/materials/scripts/gazebo.material</uri>
            <name>Gazebo/Black</name>
          </script>
        </material>
      </visual>
      <collision name='collision'>
        <pose frame=''>0 0 0 0 1.5707 1.5707</pose>
        <geometry>
          <cylinder>
            <!-- <radius>0.02</radius>
            <length>0.005</length> -->
            <radius>0.017</radius>
            <length>0.003</length>
          </cylinder>
        </geometry>
        <surface>
          <friction>
            <ode>
              <!-- <mu>0</mu>
              <mu2>0</mu2> -->
              <!-- <mu>1</mu>
              <mu2>1</mu2> -->
              <!-- <mu>0.7</mu>
              <mu2>0.7</mu2> -->
              <mu>1</mu>
              <mu2>1</mu2>
              <fdir1>0 0 0</fdir1>
              <slip1>0</slip1>
              <slip2>0</slip2>
              <!-- <mu>2</mu>
              <mu2>2</mu2> -->
              <!-- A circunferência para vel 4 e 2 permaneceu igual com mu 0.7, 1 e 2. Portanto, não altera dinâmica -->
              <!-- <mu>0</mu>
              <mu2>0</mu2> -->
              <!-- <mu>1.16</mu>
              <mu2>1.16</mu2> -->
            </ode>
            <torsional>
              <coefficient>1</coefficient>
              <patch_radius>0</patch_radius>
              <surface_radius>0</surface_radius>
              <use_patch_radius>1</use_patch_radius>
              <ode>
                <slip>0</slip>
              </ode>
            </torsional>
          </friction>
          <contact>
            <ode>
              <kp>1e+13</kp>
              <kd>1</kd>
            </ode>
            <bullet>
              <kp>1e+13</kp>
              <kd>1</kd>
            </bullet>
          </contact>
        </surface>
      </collision>
    </link>
   
    <link name='right_wheel'>
      <!-- <pose frame=''>0 -0.035 0.018 0 0 0</pose> -->
      <!-- <pose frame=''>0 -0.0345 0.019 0 0 0</pose> -->
      <!-- <pose frame=''>0 -0.0345 0.0158 0 0 0</pose> -->
      <!-- <pose frame=''>0 -0.0345 0.0155 0 0 0</pose> -->
      <pose frame=''>0 -0.0345 0.014 0 0 0</pose>
      <inertial>
        <inertia>
          <!-- <ixx>0.001</ixx> -->
          <!-- <ixx>7.3e-7</ixx> -->
          <ixx>0.000000365</ixx>
          <!-- <ixx>3.65e-7</ixx> -->
          <!-- <ixx>0.000001445</ixx> -->
          <ixy>0</ixy>
          <ixz>0</ixz>
          <!-- <iyy>0.001</iyy> -->
          <!-- <iyy>0.000001445</iyy> -->
          <!-- <iyy>7.225e-7</iyy> -->
          <iyy>0.000000723</iyy>
          <iyz>0</iyz>
          <!-- <izz>0.001</izz> -->
          <!-- <izz>7.3e-7</izz> -->
          <!-- <izz>3.65e-7</izz> -->
          <!-- <izz>0.000000723</izz> -->
          <!-- <izz>0.000001445</izz> -->
          <izz>0.000000365</izz>
        </inertia>
        <mass>0.005</mass>
        <pose frame=''>0 0 0 0 0 0</pose>
      </inertial>
      <kinematic>0</kinematic>
      <gravity>1</gravity>
      <visual name='visual'>
        <pose frame=''>0 0 0 0 1.5707 1.5707</pose>
        <geometry>
          <cylinder>
            <!-- <radius>0.02</radius>
            <length>0.005</length> -->
            <radius>0.017</radius>
            <length>0.003</length>
          </cylinder>
        </geometry>
        <material>
          <script>
            <uri>file://media/materials/scripts/gazebo.material</uri>
            <name>Gazebo/Black</name>
          </script>
        </material>
      </visual>
      <collision name='collision'>
        <pose frame=''>0 0 0 0 1.5707 1.5707</pose>
        <geometry>
          <cylinder>
            <radius>0.017</radius>
            <length>0.003</length>
          </cylinder>
        </geometry>
        <surface>
          <friction>
            <ode>
              <!-- <mu>0</mu>
              <mu2>0</mu2> -->
              <!-- <mu>1</mu>
              <mu2>1</mu2> -->
              <!-- <mu>0.7</mu>
              <mu2>0.7</mu2> -->
              <mu>1</mu>
              <mu2>1</mu2>
              <fdir1>0 0 0</fdir1>
              <slip1>0</slip1>
              <slip2>0</slip2>
              <!-- <mu>2</mu>
              <mu2>2</mu2> -->
              <!-- A circunferência para vel 4 e 2 permaneceu igual com mu 0.7, 1 e 2. Portanto, não altera dinâmica -->
              <!-- <mu>0</mu>
              <mu2>0</mu2> -->
              <!-- <mu>1.16</mu>
              <mu2>1.16</mu2> -->
            </ode>
            <torsional>
              <coefficient>1</coefficient>
              <patch_radius>0</patch_radius>
              <surface_radius>0</surface_radius>
              <use_patch_radius>1</use_patch_radius>
              <ode>
                <slip>0</slip>
              </ode>
            </torsional>
          </friction>
          <contact>
            <ode>
              <kp>1e+13</kp>
              <kd>1</kd>
            </ode>
            <bullet>
              <kp>1e+13</kp>
              <kd>1</kd>
            </bullet>
          </contact>
        </surface>
      </collision>
    </link>
   
    <joint name='left_wheel' type='revolute'>
      <parent>base</parent>
      <child>left_wheel</child>
      <pose frame=''>0 0 0 0 0 0</pose>
      <axis>
        <xyz>0 1 0</xyz>
        <!-- <use_parent_model_frame>1</use_parent_model_frame> -->
        <use_parent_model_frame>0</use_parent_model_frame>
        <dynamics>
          <damping>0</damping>
          <friction>0</friction>
        </dynamics>
      </axis>
    </joint>
   
    <joint name='right_wheel' type='revolute'>
      <parent>base</parent>
      <child>right_wheel</child>
      <pose frame=''>0 0 0 0 0 0</pose>
      <axis>
        <xyz>0 1 0</xyz>
        <!-- <use_parent_model_frame>1</use_parent_model_frame> -->
        <use_parent_model_frame>0</use_parent_model_frame>
        <dynamics>
          <damping>0</damping>
          <friction>0</friction>
        </dynamics>
      </axis>
    </joint>

    <plugin name='differential_drive_controller' filename='libgazebo_ros_diff_drive.so'>
      <alwaysOn>true</alwaysOn>
      <updateRate>33</updateRate>
      <leftJoint>left_wheel</leftJoint>
      <rightJoint>right_wheel</rightJoint>
      <wheelSeparation>0.069</wheelSeparation>
      <wheelDiameter>0.034</wheelDiameter>
      <!-- <torque>0.0345</torque> -->
      <torque>0.019862</torque>
      <commandTopic>cmd_vel_home1</commandTopic>
      <odometryTopic>odom</odometryTopic>
      <odometryFrame>odom</odometryFrame>
      <robotBaseFrame>base</robotBaseFrame>
    </plugin>

  </model>
</sdf>
