<?xml version='1.0'?>
<sdf version='1.6'>

  <model name='vsssoccer_robot'>

    <link name='base'>
      <inertial>
        <pose frame=''>0.001453 -0.000453 0.029787 0 0 0</pose> <!-- m m m rad rad rad -->
        <inertia>
          <ixx>0.0004219</ixx> <!-- kg.m² -->
          <iyy>0.0004219</iyy>
          <izz>0.0004219</izz>
          <ixy>0</ixy>
          <ixz>0</ixz>
          <iyz>0</iyz>
        </inertia>
        <mass>0.45</mass> <!-- kg -->
      </inertial>
      <pose frame=''>0 0 0 0 0 0</pose>
      <kinematic>0</kinematic>
      <gravity>1</gravity>

      <visual name='base_visual'>
        <pose frame=''>0 0 0.04 0 0 0</pose>
        <geometry>
          <box>
            <size>0.075 0.075 0.075</size>
          </box>
        </geometry>
        <material>
          <script>
            <uri>file://media/materials/scripts/gazebo.material</uri>
            <name>Gazebo/White</name>
          </script>
        </material>
      </visual>
      <collision name='base_collision'>
        <pose frame=''>0 0 0.04 0 0 0</pose>
        <geometry>
          <box>
            <size>0.075 0.075 0.075</size>
          </box>
        </geometry>
        <surface>
          <friction>
            <ode>
              <mu>0.24</mu>
              <mu2>0.24</mu2>
            </ode>
          </friction>
          <contact>
            <ode>
              <kp>1e+13</kp>
              <kd>1</kd>
            </ode>
            <bullet>
              <kp>1e+13</kp>
              <kd>1</kd>
            </bullet>
          </contact>
        </surface>
      </collision>
  
      <visual name='rear_wheel_visual'>
        <pose frame=''>-0.0325 0 0.004 0 1.5707 1.5707</pose>
        <geometry>
          <sphere>
            <radius>0.005</radius>
          </sphere>
        </geometry>
        <material>
          <script>
            <uri>file://media/materials/scripts/gazebo.material</uri>
            <name>Gazebo/Black</name>
          </script>
        </material>
      </visual>
      <collision name='rear_wheel_collision'>
        <pose frame=''>-0.0325 0 0.004 0 1.5707 1.5707</pose>
        <geometry>
          <sphere>
            <radius>0.005</radius>
          </sphere>
        </geometry>
        <surface>
          <friction>
            <ode>
              <mu>0.15</mu>
              <mu2>0.15</mu2>
              <fdir1>1 0 0</fdir1>
              <slip1>0</slip1>
              <slip2>0</slip2>
            </ode>
            <torsional>
              <coefficient>0.001</coefficient>
              <patch_radius>2</patch_radius>
              <surface_radius>0</surface_radius>
              <use_patch_radius>1</use_patch_radius>
              <ode>
                <slip>0</slip>
              </ode>
            </torsional>
          </friction>
          <bounce>
            <restitution_coefficient>0</restitution_coefficient>
            <threshold>1e+06</threshold>
          </bounce>
          <contact>
            <collide_without_contact>0</collide_without_contact>
            <collide_without_contact_bitmask>1</collide_without_contact_bitmask>
            <collide_bitmask>1</collide_bitmask>
            <ode>
              <soft_cfm>0</soft_cfm>
              <soft_erp>0.2</soft_erp>
              <kp>1e+13</kp>
              <kd>1</kd>
              <max_vel>0.01</max_vel>
              <min_depth>0.003</min_depth>
            </ode>
            <bullet>
              <split_impulse>1</split_impulse>
              <split_impulse_penetration_threshold>-0.01</split_impulse_penetration_threshold>
              <soft_cfm>0</soft_cfm>
              <soft_erp>0.2</soft_erp>
              <kp>1e+13</kp>
              <kd>1</kd>
            </bullet>
          </contact>
        </surface>
      </collision>

      <visual name='front_wheel_visual'>
        <pose frame=''>0.0325 0 0.004 0 1.5707 1.5707</pose>
        <geometry>
          <sphere>
            <radius>0.005</radius>
          </sphere>
        </geometry>
        <material>
          <script>
            <uri>file://media/materials/scripts/gazebo.material</uri>
            <name>Gazebo/Black</name>
          </script>
        </material>
      </visual>
      <collision name='front_wheel_collision'>
        <pose frame=''>0.0325 0 0.004 0 1.5707 1.5707</pose>
        <geometry>
          <sphere>
            <radius>0.005</radius>
          </sphere>
        </geometry>
        <surface>
          <friction>
            <ode>
              <mu>0.15</mu>
              <mu2>0.15</mu2>
              <fdir1>1 0 0</fdir1>
              <slip1>0</slip1>
              <slip2>0</slip2>
            </ode>
            <torsional>
              <coefficient>0.001</coefficient>
              <patch_radius>2</patch_radius>
              <surface_radius>0</surface_radius>
              <use_patch_radius>1</use_patch_radius>
              <ode>
                <slip>0</slip>
              </ode>
            </torsional>
          </friction>
          <bounce>
            <restitution_coefficient>0</restitution_coefficient>
            <threshold>1e+06</threshold>
          </bounce>
          <contact>
            <collide_without_contact>0</collide_without_contact>
            <collide_without_contact_bitmask>1</collide_without_contact_bitmask>
            <collide_bitmask>1</collide_bitmask>
            <ode>
              <soft_cfm>0</soft_cfm>
              <soft_erp>0.2</soft_erp>
              <kp>1e+13</kp>
              <kd>1</kd>
              <max_vel>0.01</max_vel>
              <min_depth>0.003</min_depth>
            </ode>
            <bullet>
              <split_impulse>1</split_impulse>
              <split_impulse_penetration_threshold>-0.01</split_impulse_penetration_threshold>
              <soft_cfm>0</soft_cfm>
              <soft_erp>0.2</soft_erp>
              <kp>1e+13</kp>
              <kd>1</kd>
            </bullet>
          </contact>
        </surface>
      </collision>
    </link>
 
    <link name='left_wheel'>
      <pose frame=''>0 0.0345 0.015 0 0 0</pose>
      <inertial>
        <inertia>
          <ixx>0.000000365</ixx>
          <iyy>0.000000723</iyy>
          <izz>0.000000365</izz>
          <ixy>0</ixy>
          <ixz>0</ixz>
          <iyz>0</iyz>
        </inertia>
        <mass>0.005</mass>
        <pose frame=''>0 0 0 0 0 0</pose>
      </inertial>
      <kinematic>0</kinematic>
      <gravity>1</gravity>
      <visual name='visual'>
        <pose frame=''>0 0 0 0 1.5707 1.5707</pose>
        <geometry>
          <cylinder>
            <radius>0.017</radius>
            <length>0.003</length>
          </cylinder>
        </geometry>
        <material>
          <script>
            <uri>file://media/materials/scripts/gazebo.material</uri>
            <name>Gazebo/Black</name>
          </script>
        </material>
      </visual>
      <collision name='collision'>
        <pose frame=''>0 0 0 0 1.5707 1.5707</pose>
        <geometry>
          <cylinder>
            <radius>0.017</radius>
            <length>0.003</length>
          </cylinder>
        </geometry>
        <surface>
          <friction>
            <ode>
              <mu>1</mu>
              <mu2>1</mu2>
              <fdir1>0 0 0</fdir1>
              <slip1>0</slip1>
              <slip2>0</slip2>
            </ode>
            <torsional>
              <coefficient>1</coefficient>
              <patch_radius>0</patch_radius>
              <surface_radius>0</surface_radius>
              <use_patch_radius>1</use_patch_radius>
              <ode>
                <slip>0</slip>
              </ode>
            </torsional>
          </friction>
          <bounce>
            <restitution_coefficient>0</restitution_coefficient>
            <threshold>1e+06</threshold>
          </bounce>
          <contact>
            <collide_without_contact>0</collide_without_contact>
            <collide_without_contact_bitmask>1</collide_without_contact_bitmask>
            <collide_bitmask>1</collide_bitmask>
            <ode>
              <soft_cfm>0</soft_cfm>
              <soft_erp>0.2</soft_erp>
              <kp>1e+13</kp>
              <kd>1</kd>
              <max_vel>0.01</max_vel>
              <!-- <min_depth>0</min_depth> -->
              <min_depth>0.003</min_depth>
            </ode>
            <bullet>
              <split_impulse>1</split_impulse>
              <split_impulse_penetration_threshold>-0.01</split_impulse_penetration_threshold>
              <soft_cfm>0</soft_cfm>
              <soft_erp>0.2</soft_erp>
              <kp>1e+13</kp>
              <kd>1</kd>
            </bullet>
          </contact>
        </surface>

      </collision>
    </link>
   
    <link name='right_wheel'>
      <pose frame=''>0 -0.0345 0.015 0 0 0</pose>
      <inertial>
        <inertia>
          <ixx>0.000000365</ixx>
          <ixy>0</ixy>
          <ixz>0</ixz>
          <iyy>0.000000723</iyy>
          <iyz>0</iyz>
          <izz>0.000000365</izz>
        </inertia>
        <mass>0.005</mass>
        <pose frame=''>0 0 0 0 0 0</pose>
      </inertial>
      <kinematic>0</kinematic>
      <gravity>1</gravity>
      <visual name='visual'>
        <pose frame=''>0 0 0 0 1.5707 1.5707</pose>
        <geometry>
          <cylinder>
            <radius>0.017</radius>
            <length>0.003</length>
          </cylinder>
        </geometry>
        <material>
          <script>
            <uri>file://media/materials/scripts/gazebo.material</uri>
            <name>Gazebo/Black</name>
          </script>
        </material>
      </visual>
      <collision name='collision'>
        <pose frame=''>0 0 0 0 1.5707 1.5707</pose>
        <geometry>
          <cylinder>
            <radius>0.017</radius>
            <length>0.003</length>
          </cylinder>
        </geometry>
        <surface>
          <friction>
            <ode>
              <mu>1</mu>
              <mu2>1</mu2>
              <fdir1>0 0 0</fdir1>
              <slip1>0</slip1>
              <slip2>0</slip2>
            </ode>
            <torsional>
              <coefficient>1</coefficient>
              <patch_radius>0</patch_radius>
              <surface_radius>0</surface_radius>
              <use_patch_radius>1</use_patch_radius>
              <ode>
                <slip>0</slip>
              </ode>
            </torsional>
          </friction>
          <bounce>
            <restitution_coefficient>0</restitution_coefficient>
            <threshold>1e+06</threshold>
          </bounce>
          <contact>
            <collide_without_contact>0</collide_without_contact>
            <collide_without_contact_bitmask>1</collide_without_contact_bitmask>
            <collide_bitmask>1</collide_bitmask>
            <ode>
              <soft_cfm>0</soft_cfm>
              <soft_erp>0.2</soft_erp>
              <kp>1e+13</kp>
              <kd>1</kd>
              <max_vel>0.01</max_vel>
              <min_depth>0.003</min_depth>
            </ode>
            <bullet>
              <split_impulse>1</split_impulse>
              <split_impulse_penetration_threshold>-0.01</split_impulse_penetration_threshold>
              <soft_cfm>0</soft_cfm>
              <soft_erp>0.2</soft_erp>
              <kp>1e+13</kp>
              <kd>1</kd>
            </bullet>
          </contact>
        </surface>

      </collision>
    </link>
   
    <joint name='left_wheel' type='revolute'>
      <parent>base</parent>
      <child>left_wheel</child>
      <pose frame=''>0 0 0 0 0 0</pose>
      <axis>
        <xyz>0 1 0</xyz>
        <use_parent_model_frame>0</use_parent_model_frame>
        <dynamics>
          <spring_reference>0</spring_reference>
          <spring_stiffness>0</spring_stiffness>
          <damping>0</damping>
          <friction>0</friction>
        </dynamics>
      </axis>
      <physics>
        <ode>
          <limit>
            <cfm>0</cfm>
            <erp>0.2</erp>
          </limit>
          <suspension>
            <cfm>0</cfm>
            <erp>0.2</erp>
          </suspension>
        </ode>
      </physics>
    </joint>
   
    <joint name='right_wheel' type='revolute'>
      <parent>base</parent>
      <child>right_wheel</child>
      <pose frame=''>0 0 0 0 0 0</pose>
      <axis>
        <xyz>0 1 0</xyz>
        <use_parent_model_frame>0</use_parent_model_frame>
        <dynamics>
          <spring_reference>0</spring_reference>
          <spring_stiffness>0</spring_stiffness>
          <damping>0</damping>
          <friction>0</friction>
        </dynamics>
      </axis>
      <physics>
        <ode>
          <limit>
            <cfm>0</cfm>
            <erp>0.2</erp>
          </limit>
          <suspension>
            <cfm>0</cfm>
            <erp>0.2</erp>
          </suspension>
        </ode>
      </physics>
    </joint>

    <plugin name='differential_drive_controller' filename='libgazebo_ros_diff_drive.so'>
      <alwaysOn>true</alwaysOn>
      <updateRate>33</updateRate>
      <leftJoint>left_wheel</leftJoint>
      <rightJoint>right_wheel</rightJoint>
      <wheelSeparation>0.069</wheelSeparation>
      <wheelDiameter>0.034</wheelDiameter>
      <torque>0.019862</torque>
      <commandTopic>cmd_vel_home1</commandTopic>
      <odometryTopic>odom</odometryTopic>
      <odometryFrame>odom</odometryFrame>
      <robotBaseFrame>base</robotBaseFrame>
    </plugin>

  </model>
</sdf>
