<?xml version='1.0'?>
<sdf version='1.6'>

  <model name='vsssoccer_robot'>

    <link name='base'>
      <inertial>
        <pose frame=''>0.001453 -0.000453 0.029787 0 0 0</pose> <!-- m m m rad rad rad -->
        <inertia>
          <ixx>0.0004219</ixx> <!-- kg.m² -->
          <ixy>0</ixy>
          <ixz>0</ixz>
          <iyy>0.055</iyy>
          <iyz>0</iyz>
          <izz>0.0004219</izz>
        </inertia>
        <mass>0.45</mass> <!-- kg -->
      </inertial>
      <pose frame=''>0 0 0 0 0 0</pose>
      <kinematic>0</kinematic>
      <gravity>1</gravity>

      <visual name='base_visual'>
        <pose frame=''>0 0 0.04 0 0 0</pose>
        <geometry>
          <box>
            <size>0.075 0.075 0.075</size>
          </box>
        </geometry>
        <material>
          <script>
            <uri>file://media/materials/scripts/gazebo.material</uri>
            <name>Gazebo/Black</name>
          </script>
        </material>
      </visual>
      <collision name='base_collision'>
        <pose frame=''>0 0 0.04 0 0 0</pose>
        <geometry>
          <box>
            <size>0.075 0.075 0.075</size>
          </box>
        </geometry>
        <surface>
          <friction>
            <ode>
              <mu>0.8</mu>
              <mu2>0.8</mu2>
            </ode>
          </friction>
        </surface>
      </collision>
  
      <visual name='rear_wheel_visual'>
        <pose frame=''>-0.0325 0 0.004 0 0 0</pose>
        <geometry>
          <sphere>
            <radius>0.005</radius>
          </sphere>
        </geometry>
        <material>
          <script>
            <uri>file://media/materials/scripts/gazebo.material</uri>
            <name>Gazebo/White</name>
          </script>
        </material>
      </visual>
      <collision name='rear_wheel_collision'>
        <pose frame=''>-0.0325 0 0.004 0 0 0</pose>
        <geometry>
          <sphere>
            <radius>0.005</radius>
          </sphere>
        </geometry>
        <surface>
          <friction>
            <ode>
              <mu>0.3</mu>
              <mu2>0.3</mu2>
            </ode>
          </friction>
        </surface>
      </collision>

      <visual name='front_wheel_visual'>
        <pose frame=''>0.0325 0 0.004 0 0 0</pose>
        <geometry>
          <sphere>
            <radius>0.005</radius>
          </sphere>
        </geometry>
        <material>
          <script>
            <uri>file://media/materials/scripts/gazebo.material</uri>
            <name>Gazebo/White</name>
          </script>
        </material>
      </visual>
      <collision name='front_wheel_collision'>
        <pose frame=''>0.0325 0 0.004 0 0 0</pose>
        <geometry>
          <sphere>
            <radius>0.005</radius>
          </sphere>
        </geometry>
        <surface>
          <friction>
            <ode>
              <mu>0.3</mu>
              <mu2>0.3</mu2>
            </ode>
          </friction>
        </surface>
      </collision>
    </link>
 
    <link name='left_wheel'>
      <pose frame=''>0 0.0345 0.0158 0 0 0</pose>
      <inertial>
        <inertia>
          <ixx>3.65e-7</ixx>
          <ixy>0</ixy>
          <ixz>0</ixz>
          <iyy>7.225e-7</iyy>
          <iyz>0</iyz>
          <izz>3.65e-7</izz>
        </inertia>
        <mass>0.005</mass>
        <pose frame=''>0 0 0 0 0 0</pose>
      </inertial>
      <kinematic>0</kinematic>
      <gravity>1</gravity>
      <visual name='visual'>
        <pose frame=''>0 0 0 0 1.5707 1.5707</pose>
        <geometry>
          <cylinder>
            <radius>0.017</radius>
            <length>0.003</length>
          </cylinder>
        </geometry>
        <material>
          <script>
            <uri>file://media/materials/scripts/gazebo.material</uri>
            <name>Gazebo/White</name>
          </script>
        </material>
      </visual>
      <collision name='collision'>
        <pose frame=''>0 0 0 0 1.5707 1.5707</pose>
        <geometry>
          <cylinder>
            <radius>0.017</radius>
            <length>0.003</length>
          </cylinder>
        </geometry>
        <surface>
          <friction>
            <ode>
              <mu>0.7</mu>
              <mu2>0.7</mu2>
            </ode>
          </friction>
        </surface>
      </collision>
    </link>
   
    <link name='right_wheel'>
      <pose frame=''>0 -0.0345 0.0158 0 0 0</pose>
      <inertial>
        <inertia>
          <ixx>3.65e-7</ixx>
          <ixy>0</ixy>
          <ixz>0</ixz>
          <iyy>7.225e-7</iyy>
          <iyz>0</iyz>
          <izz>3.65e-7</izz>
        </inertia>
        <mass>0.005</mass>
        <pose frame=''>0 0 0 0 0 0</pose>
      </inertial>
      <kinematic>0</kinematic>
      <gravity>1</gravity>
      <visual name='visual'>
        <pose frame=''>0 0 0 0 1.5707 1.5707</pose>
        <geometry>
          <cylinder>
            <radius>0.017</radius>
            <length>0.003</length>
          </cylinder>
        </geometry>
        <material>
          <script>
            <uri>file://media/materials/scripts/gazebo.material</uri>
            <name>Gazebo/White</name>
          </script>
        </material>
      </visual>
      <collision name='collision'>
        <pose frame=''>0 0 0 0 1.5707 1.5707</pose>
        <geometry>
          <cylinder>
            <radius>0.017</radius>
            <length>0.003</length>
          </cylinder>
        </geometry>
        <surface>
          <friction>
            <ode>
              <mu>0.7</mu>
              <mu2>0.7</mu2>
            </ode>
          </friction>
        </surface>
      </collision>
    </link>
   
    <joint name='left_wheel' type='revolute'>
      <parent>base</parent>
      <child>left_wheel</child>
      <pose frame=''>0 0 0 0 0 0</pose>
      <axis>
        <xyz>0 1 0</xyz>
        <use_parent_model_frame>0</use_parent_model_frame>
        <dynamics>
          <damping>0</damping>
          <friction>0</friction>
        </dynamics>
      </axis>
    </joint>
   
    <joint name='right_wheel' type='revolute'>
      <parent>base</parent>
      <child>right_wheel</child>
      <pose frame=''>0 0 0 0 0 0</pose>
      <axis>
        <xyz>0 1 0</xyz>
        <use_parent_model_frame>0</use_parent_model_frame>
        <dynamics>
          <damping>0</damping>
          <friction>0</friction>
        </dynamics>
      </axis>
    </joint>

    <plugin name='differential_drive_controller' filename='libgazebo_ros_diff_drive.so'>
      <alwaysOn>true</alwaysOn>
      <updateRate>33</updateRate>
      <leftJoint>left_wheel</leftJoint>
      <rightJoint>right_wheel</rightJoint>
      <wheelSeparation>0.069</wheelSeparation>
      <wheelDiameter>0.034</wheelDiameter>
      <torque>0.019862</torque>
      <commandTopic>cmd_vel_guest2</commandTopic>
      <odometryTopic>odom</odometryTopic>
      <odometryFrame>odom</odometryFrame>
      <robotBaseFrame>base</robotBaseFrame>
    </plugin>

  </model>
</sdf>
